#VRML_SIM R2023b utf8

EXTERNPROTO "https://raw.githubusercontent.com/cyberbotics/webots/R2023b/projects/objects/backgrounds/protos/TexturedBackground.proto"
EXTERNPROTO "https://raw.githubusercontent.com/cyberbotics/webots/R2023b/projects/objects/backgrounds/protos/TexturedBackgroundLight.proto"
EXTERNPROTO "https://raw.githubusercontent.com/cyberbotics/webots/R2023b/projects/appearances/protos/GalvanizedMetal.proto"
EXTERNPROTO "https://raw.githubusercontent.com/cyberbotics/webots/R2023b/projects/objects/road/protos/StraightRoadSegment.proto"
EXTERNPROTO "https://raw.githubusercontent.com/cyberbotics/webots/R2023b/projects/objects/road/protos/RoadLine.proto"
EXTERNPROTO "https://raw.githubusercontent.com/cyberbotics/webots/R2023b/projects/objects/obstacles/protos/OilBarrel.proto"
EXTERNPROTO "https://raw.githubusercontent.com/cyberbotics/webots/R2023b/projects/appearances/protos/Plastic.proto"

WorldInfo {
  info [
    "Description: Examples of four wheels vehicles"
  ]
  title "Four Wheels"
  basicTimeStep 16
  FPS 32
  lineScale 0.2
  contactProperties [
    ContactProperties {
      material1 "FloorContact"
      material2 "Caster"
      coulombFriction [
        0
      ]
      bounce 0
      bounceVelocity 0
    }
    ContactProperties {
      material1 "WheelContact"
      material2 "FloorContact"
      coulombFriction [
        0.8
      ]
      bounce 0.2
      maxContactJoints 20
    }
  ]
}
Viewpoint {
  orientation 0.6019093526127498 -0.5670657997614547 -0.5622646262910392 4.2424859024909605
  position 2.9727800722563407 2.3354463343895233 20.97705442671241
}
TexturedBackground {
}
TexturedBackgroundLight {
}
StraightRoadSegment {
  translation -0.39 2.5 0
  name "road(1)"
  width 6
  numberOfLanes 1
  lines [
    RoadLine {
      type "continuous"
    }
  ]
  bottom TRUE
  length 7
  roadBoundingObject TRUE
  contactMaterial "FloorContact"
}
OilBarrel {
  translation 3.14 5.42 0.44
  physics Physics {
  }
}
DEF TWO_WHEEL_DRIVE Robot {
  translation 0 0 0.082
  children [
    DistanceSensor {
      translation 0 0.2 0
      rotation 0 0 1 1.570796327
      children [
        DEF SENSOR Shape {
          appearance Plastic {
          }
          geometry Box {
            size 0.01 0.01 0.01
          }
        }
      ]
      boundingObject USE SENSOR
      physics Physics {
      }
      lookupTable [
        0 0 0
        2 1000 0
      ]
      type "sonar"
    }
    Solid {
      translation 0 -0.2 -0.03
      children [
        DEF CASTER Shape {
          appearance GalvanizedMetal {
          }
          geometry Sphere {
            radius 0.05
          }
        }
      ]
      name "caster"
      contactMaterial "Caster"
      boundingObject USE CASTER
      physics Physics {
      }
    }
    Compass {
      translation 0 0 0.05
      children [
        DEF compass Shape {
          geometry Cylinder {
            height 0.02
            radius 0.05
          }
        }
      ]
      boundingObject USE compass
      physics Physics {
      }
    }
    DEF BODY_SHAPE Shape {
      appearance PBRAppearance {
        baseColor 0 0.6 1
        roughness 1
        metalness 0.5
      }
      geometry Box {
        size 0.3 0.4 0.1
      }
    }
    DEF FRONT_RIGHT_WHEEL HingeJoint {
      jointParameters HingeJointParameters {
        axis -1 0 0
        anchor 0.180975 0.1651 0
      }
      device [
        PositionSensor {
          name "right_pos"
        }
        RotationalMotor {
          name "right_wheel"
        }
      ]
      endPoint Solid {
        translation 0.18122 0.16513648034152356 0.00037221658302973894
        rotation -1 0 0 0
        children [
          DEF WHEEL_ROT Pose {
            rotation 0 -1 0 1.5708
            children [
              Shape {
                appearance PBRAppearance {
                  baseColor 0.8 0 0
                  roughness 1
                  metalness 0.8
                }
                geometry DEF WHEEL_CYL Cylinder {
                  height 0.04
                  radius 0.08
                }
              }
            ]
          }
        ]
        name "front right wheel"
        contactMaterial "WheelContact"
        boundingObject USE WHEEL_ROT
        physics Physics {
          mass 5
        }
      }
    }
    DEF FRONT_LEFT_WHEEL HingeJoint {
      jointParameters HingeJointParameters {
        axis -1 0 0
        anchor -0.180975 0.1651 0
      }
      device [
        PositionSensor {
          name "left_pos"
        }
        RotationalMotor {
          name "left_wheel"
        }
      ]
      endPoint Solid {
        translation -0.18122 0.165474 0
        rotation -1 0 0 0
        children [
          USE WHEEL_ROT
        ]
        name "front left wheel"
        contactMaterial "WheelContact"
        boundingObject USE WHEEL_ROT
        physics Physics {
          mass 5
        }
      }
    }
  ]
  name "front_wheel_drive"
  boundingObject USE BODY_SHAPE
  physics Physics {
    mass 1
  }
  controller "robotControl"
}
