#VRML_SIM R2023b utf8

EXTERNPROTO "https://raw.githubusercontent.com/cyberbotics/webots/R2023b/projects/objects/backgrounds/protos/TexturedBackground.proto"
EXTERNPROTO "https://raw.githubusercontent.com/cyberbotics/webots/R2023b/projects/objects/backgrounds/protos/TexturedBackgroundLight.proto"
EXTERNPROTO "https://raw.githubusercontent.com/cyberbotics/webots/R2023b/projects/appearances/protos/Copper.proto"
EXTERNPROTO "https://raw.githubusercontent.com/cyberbotics/webots/R2023b/projects/appearances/protos/GalvanizedMetal.proto"
EXTERNPROTO "https://raw.githubusercontent.com/cyberbotics/webots/R2023b/projects/objects/road/protos/StraightRoadSegment.proto"
EXTERNPROTO "https://raw.githubusercontent.com/cyberbotics/webots/R2023b/projects/objects/road/protos/RoadLine.proto"

WorldInfo {
  info [
    "Description: Examples of four wheels vehicles"
  ]
  title "Four Wheels"
  basicTimeStep 16
  FPS 32
  lineScale 0.2
  contactProperties [
    ContactProperties {
      material1 "FloorContact"
      material2 "Caster"
      coulombFriction [
        0
      ]
      bounce 0
      bounceVelocity 0
    }
    ContactProperties {
      material1 "WheelContact"
      material2 "FloorContact"
      coulombFriction [
        0.8
      ]
      bounce 0.2
      maxContactJoints 20
    }
  ]
}
Viewpoint {
  orientation 0.25735186561336654 -0.33514986698660254 -0.9063358008620107 4.661928750835658
  position 1.3034472479612664 -8.632545633441833 5.799217226447372
}
TexturedBackground {
}
TexturedBackgroundLight {
}
StraightRoadSegment {
  translation -0.39 2.5 0
  name "road(1)"
  width 6
  numberOfLanes 1
  lines [
    RoadLine {
      type "continuous"
    }
  ]
  bottom TRUE
  length 7
  roadBoundingObject TRUE
  contactMaterial "FloorContact"
}
Solid {
  translation -2.86 1.61 0.5
  children [
    DEF box Shape {
      appearance Copper {
      }
      geometry Box {
        size 1 1 1
      }
    }
  ]
  boundingObject USE box
  physics Physics {
    mass 1
  }
}
DEF TWO_WHEEL_DRIVE Robot {
  translation 0 0 0.082
  children [
    Pen {
      name "TRACK_PEN"
      inkColor 1 0 0
      inkDensity 1
      leadSize 0.02
      write FALSE
    }
    Solid {
      translation 0 -0.2 -0.03
      children [
        DEF CASTER Shape {
          appearance GalvanizedMetal {
          }
          geometry Sphere {
            radius 0.05
          }
        }
      ]
      name "caster"
      contactMaterial "Caster"
      boundingObject USE CASTER
      physics Physics {
      }
    }
    Compass {
      translation 0 0 0.05
      children [
        DEF compass Shape {
          geometry Cylinder {
            height 0.02
            radius 0.05
          }
        }
      ]
      boundingObject USE compass
      physics Physics {
      }
    }
    DEF BODY_SHAPE Shape {
      appearance PBRAppearance {
        baseColor 0 0.6 1
        roughness 1
        metalness 0.5
      }
      geometry Box {
        size 0.3 0.4 0.1
      }
    }
    DEF FRONT_RIGHT_WHEEL HingeJoint {
      jointParameters HingeJointParameters {
        axis -1 0 0
        anchor 0.180975 0.1651 0
      }
      device [
        PositionSensor {
          name "right_pos"
        }
        RotationalMotor {
          name "right_wheel"
        }
      ]
      endPoint Solid {
        translation 0.18121970955473965 0.16547422494720598 -0.00011918096786542414
        rotation 0.006079601616780442 -0.9999663235963087 0.0055127232348293085 6.279297135597885
        children [
          DEF WHEEL_ROT Pose {
            rotation 0 -1 0 1.5708
            children [
              Shape {
                appearance PBRAppearance {
                  baseColor 0.8 0 0
                  roughness 1
                  metalness 0.8
                }
                geometry DEF WHEEL_CYL Cylinder {
                  height 0.04
                  radius 0.08
                }
              }
            ]
          }
        ]
        name "front right wheel"
        contactMaterial "WheelContact"
        boundingObject USE WHEEL_ROT
        physics Physics {
          mass 5
        }
      }
    }
    DEF FRONT_LEFT_WHEEL HingeJoint {
      jointParameters HingeJointParameters {
        axis -1 0 0
        anchor -0.180975 0.1651 0
      }
      device [
        PositionSensor {
          name "left_pos"
        }
        RotationalMotor {
          name "left_wheel"
        }
      ]
      endPoint Solid {
        translation -0.18122 0.1651 0
        rotation -6.0548295845204214e-05 0.8751732005682115 -0.48380974084974426 6.283178578055409
        children [
          USE WHEEL_ROT
        ]
        name "front left wheel"
        contactMaterial "WheelContact"
        boundingObject USE WHEEL_ROT
        physics Physics {
          mass 5
        }
      }
    }
  ]
  name "front_wheel_drive"
  boundingObject USE BODY_SHAPE
  physics Physics {
    mass 1
  }
  controller "main"
}
